<?xml version="1.0" ?>
<!-- =================================================================================== -->
<!-- |    This document was autogenerated by xacro from robot_links_and_joints.xacro   | -->
<!-- |    EDITING THIS FILE BY HAND IS NOT RECOMMENDED                                 | -->
<!-- =================================================================================== -->
<robot name="anh_robot" xmlns:xacro="http://www.ros.org/wiki/xacro">
  <joint name="base_laser_vert_bottom_joint" type="fixed">
    <axis xyz="0 0 1"/>
    <origin rpy="3.1354753 -1.3045001 0.0024658" xyz="0.3157894464801903 -0.002068548615034871 0.5099999434059285"/>
    <parent link="base"/>
    <child link="laser_vert_bottom"/>
  </joint>
  <link name="laser_vert_bottom">
    <collision>
      <origin rpy="0 0 0" xyz="0 0 0"/>
      <geometry>
        <box size="0.1 0.1 0.1"/>
      </geometry>
    </collision>
    <visual>
      <origin rpy="0 0 0" xyz="0 0 0"/>
      <geometry>
        <mesh filename="package://gazebo_plugins/test/multi_robot_scenario/meshes/laser/hokuyo.dae"/>
      </geometry>
    </visual>
    <inertial>
      <mass value="1e-5"/>
      <origin rpy="0 0 0" xyz="0 0 0"/>
      <inertia ixx="1e-6" ixy="0" ixz="0" iyy="1e-6" iyz="0" izz="1e-6"/>
    </inertial>
  </link>
  <gazebo reference="laser_vert_bottom">
    <sensor name="laser" type="ray">
      <pose>0 0 0 0 0 0</pose>
      <ray>
        <scan>
          <horizontal>
            <!-- The URG-04LX-UG01  has  683 steps with 0.35139 Degree resolution -->
            <resolution>1</resolution>
            <max_angle>2.0944</max_angle>
            <!-- 120 Degree -->
            <min_angle>-2.0944</min_angle>
            <!-- -120 Degree -->
            <samples>683</samples>
          </horizontal>
        </scan>
        <range>
          <min>0.08</min>
          <max>5</max>
          <resolution>0.01</resolution>
        </range>
      </ray>
      <plugin filename="libgazebo_ros_laser.so" name="laser">
        <robotNamespace/>
        <topicName>laser_vert_bottom/scan</topicName>
        <frameName>laser_vert_bottom</frameName>
      </plugin>
      <!--
          <plugin name="laser" filename="libRayPlugin.so" />
          -->
      <always_on>1</always_on>
      <update_rate>30</update_rate>
      <visualize>true</visualize>
    </sensor>
  </gazebo>
  <joint name="base_laser_vert_top_right_joint" type="fixed">
    <axis xyz="0 0 1"/>
    <origin rpy="-1.176 0.6313 -1.9377" xyz="0.2978 -0.1450 1.8451"/>
    <parent link="base"/>
    <child link="laser_vert_top_right"/>
  </joint>
  <link name="laser_vert_top_right">
    <collision>
      <origin rpy="0 0 0" xyz="0 0 0"/>
      <geometry>
        <box size="0.1 0.1 0.1"/>
      </geometry>
    </collision>
    <visual>
      <origin rpy="0 0 0" xyz="0 0 0"/>
      <geometry>
        <mesh filename="package://gazebo_plugins/test/multi_robot_scenario/meshes/laser/hokuyo.dae"/>
      </geometry>
    </visual>
    <inertial>
      <mass value="1e-5"/>
      <origin rpy="0 0 0" xyz="0 0 0"/>
      <inertia ixx="1e-6" ixy="0" ixz="0" iyy="1e-6" iyz="0" izz="1e-6"/>
    </inertial>
  </link>
  <gazebo reference="laser_vert_top_right">
    <sensor name="laser" type="ray">
      <pose>0 0 0 0 0 0</pose>
      <ray>
        <scan>
          <horizontal>
            <!-- The URG-04LX-UG01  has  683 steps with 0.35139 Degree resolution -->
            <resolution>1</resolution>
            <max_angle>2.0944</max_angle>
            <!-- 120 Degree -->
            <min_angle>-2.0944</min_angle>
            <!-- -120 Degree -->
            <samples>683</samples>
          </horizontal>
        </scan>
        <range>
          <min>0.08</min>
          <max>5</max>
          <resolution>0.01</resolution>
        </range>
      </ray>
      <plugin filename="libgazebo_ros_laser.so" name="laser">
        <robotNamespace/>
        <topicName>laser_vert_top_right/scan</topicName>
        <frameName>laser_vert_top_right</frameName>
      </plugin>
      <!--
          <plugin name="laser" filename="libRayPlugin.so" />
          -->
      <always_on>1</always_on>
      <update_rate>30</update_rate>
      <visualize>true</visualize>
    </sensor>
  </gazebo>
  <joint name="base_laser_vert_top_left_joint" type="fixed">
    <axis xyz="0 0 1"/>
    <origin rpy="1.178 0.6198 1.956" xyz="0.2997 0.1531 1.8443"/>
    <parent link="base"/>
    <child link="laser_vert_top_left"/>
  </joint>
  <link name="laser_vert_top_left">
    <collision>
      <origin rpy="0 0 0" xyz="0 0 0"/>
      <geometry>
        <box size="0.1 0.1 0.1"/>
      </geometry>
    </collision>
    <visual>
      <origin rpy="0 0 0" xyz="0 0 0"/>
      <geometry>
        <mesh filename="package://gazebo_plugins/test/multi_robot_scenario/meshes/laser/hokuyo.dae"/>
      </geometry>
    </visual>
    <inertial>
      <mass value="1e-5"/>
      <origin rpy="0 0 0" xyz="0 0 0"/>
      <inertia ixx="1e-6" ixy="0" ixz="0" iyy="1e-6" iyz="0" izz="1e-6"/>
    </inertial>
  </link>
  <gazebo reference="laser_vert_top_left">
    <sensor name="laser" type="ray">
      <pose>0 0 0 0 0 0</pose>
      <ray>
        <scan>
          <horizontal>
            <!-- The URG-04LX-UG01  has  683 steps with 0.35139 Degree resolution -->
            <resolution>1</resolution>
            <max_angle>2.0944</max_angle>
            <!-- 120 Degree -->
            <min_angle>-2.0944</min_angle>
            <!-- -120 Degree -->
            <samples>683</samples>
          </horizontal>
        </scan>
        <range>
          <min>0.08</min>
          <max>5</max>
          <resolution>0.01</resolution>
        </range>
      </ray>
      <plugin filename="libgazebo_ros_laser.so" name="laser">
        <robotNamespace/>
        <topicName>laser_vert_top_left/scan</topicName>
        <frameName>laser_vert_top_left</frameName>
      </plugin>
      <!--
          <plugin name="laser" filename="libRayPlugin.so" />
          -->
      <always_on>1</always_on>
      <update_rate>30</update_rate>
      <visualize>true</visualize>
    </sensor>
  </gazebo>
  <joint name="base_laser_horiz_joint" type="fixed">
    <axis xyz="0 0 1"/>
    <origin rpy="-0.0012 0.1146 -0.0015" xyz="0.2325 0.0001 1.9201"/>
    <parent link="base"/>
    <child link="laser_horiz"/>
  </joint>
  <link name="laser_horiz">
    <collision>
      <origin rpy="0 0 0" xyz="0 0 0"/>
      <geometry>
        <box size="0.1 0.1 0.1"/>
      </geometry>
    </collision>
    <visual>
      <origin rpy="0 0 0" xyz="0 0 0"/>
      <geometry>
        <mesh filename="package://gazebo_plugins/test/multi_robot_scenario/meshes/laser/hokuyo.dae"/>
      </geometry>
    </visual>
    <inertial>
      <mass value="1e-5"/>
      <origin rpy="0 0 0" xyz="0 0 0"/>
      <inertia ixx="1e-6" ixy="0" ixz="0" iyy="1e-6" iyz="0" izz="1e-6"/>
    </inertial>
  </link>
  <gazebo reference="laser_horiz">
    <sensor name="laser" type="ray">
      <pose>0 0 0 0 0 0</pose>
      <ray>
        <scan>
          <horizontal>
            <!-- The URG-04LX-UG01  has  683 steps with 0.35139 Degree resolution -->
            <resolution>1</resolution>
            <max_angle>2.0944</max_angle>
            <!-- 120 Degree -->
            <min_angle>-2.0944</min_angle>
            <!-- -120 Degree -->
            <samples>683</samples>
          </horizontal>
        </scan>
        <range>
          <min>0.08</min>
          <max>5</max>
          <resolution>0.01</resolution>
        </range>
      </ray>
      <plugin filename="libgazebo_ros_laser.so" name="laser">
        <robotNamespace/>
        <topicName>laser_horiz/scan</topicName>
        <frameName>laser_horiz</frameName>
      </plugin>
      <!--
          <plugin name="laser" filename="libRayPlugin.so" />
          -->
      <always_on>1</always_on>
      <update_rate>30</update_rate>
      <visualize>true</visualize>
    </sensor>
  </gazebo>
  <link name="base">
    <visual>
      <geometry>
        <box size="0.94 0.78 1.98"/>
      </geometry>
    </visual>
  </link>
  <joint name="base_vert_bottom_joint" type="fixed">
    <parent link="base"/>
    <child link="laser_vert_bottom"/>
    <origin rpy="3.1355 -1.3045 0.0025" xyz="0.3158 -0.0021 0.51"/>
  </joint>
  <joint name="base_vert_top_right_joint" type="fixed">
    <parent link="base"/>
    <child link="laser_vert_top_right"/>
    <origin rpy="-1.176 0.6313 -1.9377" xyz="0.2978 -0.145 1.8451"/>
  </joint>
  <joint name="base_vert_top_left_joint" type="fixed">
    <parent link="base"/>
    <child link="laser_vert_top_left"/>
    <origin rpy="1.178 0.6198 1.956" xyz="0.2997 0.1531 1.8443"/>
  </joint>
  <joint name="base_horiz_joint" type="fixed">
    <parent link="base"/>
    <child link="laser_horiz"/>
    <origin rpy="-0.0012 0.1146 -0.0015" xyz="0.2325 0.0001 1.9201"/>
  </joint>
  <link name="wheel_center">
    <visual>
      <geometry>
        <cylinder length="0.05" radius="0.15"/>
      </geometry>
    </visual>
    <collision>
      <geometry>
        <cylinder length="0.05" radius="0.15"/>
      </geometry>
    </collision>
  </link>
  <joint name="base_wheel_center_joint" type="continuous">
    <parent link="base"/>
    <child link="wheel_center"/>
    <origin rpy="-1.57 0 0" xyz="-0.1 0 0"/>
    <limit effort="100" velocity="15"/>
    <joint_properties damping="0.0" friction="0.0"/>
  </joint>
  <link name="wheel_left">
    <visual>
      <geometry>
        <cylinder length="0.05" radius="0.2"/>
      </geometry>
    </visual>
    <collision>
      <geometry>
        <cylinder length="0.05" radius="0.2"/>
      </geometry>
    </collision>
  </link>
  <joint name="base_wheel_left_joint" type="continuous">
    <parent link="base"/>
    <child link="wheel_left"/>
    <origin rpy="-1.57 0 0" xyz="-0.1 0.4 0"/>
    <limit effort="100" velocity="15"/>
    <joint_properties damping="0.0" friction="0.0"/>
  </joint>
  <link name="wheel_right">
    <visual>
      <geometry>
        <cylinder length="0.05" radius="0.2"/>
      </geometry>
    </visual>
    <collision>
      <geometry>
        <cylinder length="0.05" radius="0.2"/>
      </geometry>
    </collision>
  </link>
  <joint name="base_wheel_right_joint" type="continuous">
    <parent link="base"/>
    <child link="wheel_right"/>
    <origin rpy="-1.57 0 0" xyz="-0.1 -0.4 0"/>
    <limit effort="100" velocity="15"/>
    <joint_properties damping="0.0" friction="0.0"/>
  </joint>
</robot>

